karolniewiadomski@MACBOOK-C02CF120MD6R UQSpice_0.02 % /usr/local/bin/python3.9 /Users/karolniewiadomski/Documents/SCENT/Research/Toolbox/UQSpice_0.02/G
UI/main.py
Exception in Tkinter callback
Traceback (most recent call last):
  File "/usr/local/Cellar/python@3.9/3.9.13_1/Frameworks/Python.framework/Versions/3.9/lib/python3.9/tkinter/__init__.py", line 1892, in __call__
    return self.func(*args)
  File "/usr/local/lib/python3.9/site-packages/customtkinter/widgets/ctk_button.py", line 368, in clicked
    self.command()
  File "/Users/karolniewiadomski/Documents/SCENT/Research/Toolbox/UQSpice_0.02/GUI/controller.py", line 155, in <lambda>
    command=lambda: guievents.get_file_path(component_parameters_frame,
  File "/Users/karolniewiadomski/Documents/SCENT/Research/Toolbox/UQSpice_0.02/GUI/gui_events.py", line 239, in get_file_path
    sketch_schematic_asc(schematic,
  File "/Users/karolniewiadomski/Documents/SCENT/Research/Toolbox/UQSpice_0.02/GUI/gui_events.py", line 340, in sketch_schematic_asc
    canvas_size = [int(size) for size in canvas_size]
  File "/Users/karolniewiadomski/Documents/SCENT/Research/Toolbox/UQSpice_0.02/GUI/gui_events.py", line 340, in <listcomp>
    canvas_size = [int(size) for size in canvas_size]
ValueError: invalid literal for int() with base 10: ''
^C%                                                                                                                                                    
karolniewiadomski@MACBOOK-C02CF120MD6R UQSpice_0.02 % /usr/local/bin/python3.9 /Users/karolniewiadomski/Documents/SCENT/Research/Toolbox/UQSpice_0.02/GUI/main.py
[]
{}
[]
Exception in Tkinter callback
Traceback (most recent call last):
karolniewiadomski@MACBOOK-C02CF120MD6R UQSpice_0.02 % /usr/local/bin/python3.9 /Users/karolniewiadomski/Documents/SCENT/Research/Toolbox/UQSpice_0.02/G
UI/gui_events.py
karolniewiadomski@MACBOOK-C02CF120MD6R UQSpice_0.02 % /usr/local/bin/python3.9 /Users/karolniewiadomski/Documents/SCENT/Research/Toolbox/UQSpice_0.02/G
UI/main.py
[]
{}
[]
Exception in Tkinter callback
Traceback (most recent call last):
  File "/usr/local/Cellar/python@3.9/3.9.13_1/Frameworks/Python.framework/Versions/3.9/lib/python3.9/tkinter/__init__.py", line 1892, in __call__
    return self.func(*args)
  File "/usr/local/lib/python3.9/site-packages/customtkinter/widgets/ctk_button.py", line 368, in clicked
    self.command()
  File "/Users/karolniewiadomski/Documents/SCENT/Research/Toolbox/UQSpice_0.02/GUI/gui_events.py", line 362, in <lambda>
    enter_parameters_button.configure(command=lambda: open_new_window(components,
  File "/Users/karolniewiadomski/Documents/SCENT/Research/Toolbox/UQSpice_0.02/GUI/gui_events.py", line 771, in open_new_window
    component_selected.set(components[0])
IndexError: list index out of range
